submitit ERROR (2024-12-02 16:48:25,608) - Submitted job triggered an exception
Traceback (most recent call last):
  File "/home/gan4090/Desktop/ENTER/envs/wsissl/lib/python3.10/runpy.py", line 196, in _run_module_as_main
    return _run_code(code, main_globals, None,
  File "/home/gan4090/Desktop/ENTER/envs/wsissl/lib/python3.10/runpy.py", line 86, in _run_code
    exec(code, run_globals)
  File "/home/gan4090/Desktop/ENTER/envs/wsissl/lib/python3.10/site-packages/submitit/core/_submit.py", line 11, in <module>
    submitit_main()
  File "/home/gan4090/Desktop/ENTER/envs/wsissl/lib/python3.10/site-packages/submitit/core/submission.py", line 71, in submitit_main
    process_job(args.folder)
  File "/home/gan4090/Desktop/ENTER/envs/wsissl/lib/python3.10/site-packages/submitit/core/submission.py", line 64, in process_job
    raise error
  File "/home/gan4090/Desktop/ENTER/envs/wsissl/lib/python3.10/site-packages/submitit/core/submission.py", line 53, in process_job
    result = delayed.result()
  File "/home/gan4090/Desktop/ENTER/envs/wsissl/lib/python3.10/site-packages/submitit/core/utils.py", line 126, in result
    self._result = self.function(*self.args, **self.kwargs)
  File "/home/gan4090/dzh/mil4wsi-main/utilsmil4wsi/process.py", line 13, in processDataset
    train_loader,val_loader,test_loader=get_loaders(args)
  File "/home/gan4090/dzh/mil4wsi-main/utilsmil4wsi/datasets.py", line 20, in get_loaders
    train_dataset = MyOwnDataset(root=args.datasetpath, type="train")
  File "/home/gan4090/dzh/mil4wsi-main/utilsmil4wsi/datasets.py", line 73, in __init__
    self.processed_dir, self.type, "*data*.pt"))
  File "/home/gan4090/Desktop/ENTER/envs/wsissl/lib/python3.10/site-packages/torch_geometric/data/dataset.py", line 105, in processed_dir
    return osp.join(self.root, 'processed')
  File "/home/gan4090/Desktop/ENTER/envs/wsissl/lib/python3.10/posixpath.py", line 76, in join
    a = os.fspath(a)
TypeError: expected str, bytes or os.PathLike object, not NoneType
